## CHANGE WAS --NOT-- MADE HERE. 
## Note: No class for Validation error so every base_assert only calls this class.
# Latest Commit has fixed this undone task, 'Note' above is INVALID now.
class FyleError(Exception):
    status_code = 400

    def __init__(self, status_code, message):
        Exception.__init__(self)
        self.message = message
        self.status_code = status_code

    def to_dict(self):
        res = dict()
        res['message'] = self.message
        return res

class ValidationError(Exception):
    status_code = 400

    def __init__(self, status_code, message):
        Exception.__init__(self)
        self.message = message
        self.status_code = status_code

    def to_dict(self):
        res = dict()
        res['message'] = self.message
        return res